{
    "project_name": "Lang",
    "bug_id": "12",
    "test_id": 0,
    "ans": [
        {
            "method_id": 3,
            "rank": 1
        },
        {
            "method_id": 2,
            "rank": 2
        },
        {
            "method_id": 1,
            "rank": 3
        },
        {
            "method_id": 0,
            "rank": 4
        },
        {
            "method_id": 4,
            "rank": 5
        }
    ],
    "final_full_answer": "To rank the methods from most suspicious to least suspicious based on the provided test, stack trace, and method coverage information, we need to analyze the context of the failing test and the methods involved.\n\n1. The test is designed to check for exceptions when invalid parameters are passed to the `random` methods of `RandomStringUtils`.\n2. The stack trace indicates that an `ArrayIndexOutOfBoundsException` occurred, which suggests that the method was trying to access an array index that does not exist.\n3. The methods that are directly involved in the test are those that handle the parameters passed to the `random` methods.\n\nGiven this context, we can rank the methods as follows:\n\n1. **Method ID 3**: `random(IIIZZ)` - This method is the most suspicious because it directly calls the method that caused the exception and handles the parameters that are being tested for invalid values.\n2. **Method ID 2**: `random(IZZ)` - This method is also suspicious as it is a direct call to the method that handles boolean flags and could lead to the same exception if the parameters are not validated properly.\n3. **Method ID 1**: `random(I)` - This method is less suspicious than the previous two but still relevant as it is a direct call to the method that could lead to the exception.\n4. **Method ID 0**: `random(I[C)` - This method is less suspicious as it deals with character arrays, but it is still part of the chain that could lead to the exception.\n5. **Method ID 4**: `random(IIIZZ[CLjava/util/Random;)` - This method is the least suspicious as it is not directly involved in the test case that caused the exception.\n\nHere is the JSON output reflecting the rankings:\n\n```json\n[\n    {\n        \"method_id\": 3,\n        \"rank\": 1\n    },\n    {\n        \"method_id\": 2,\n        \"rank\": 2\n    },\n    {\n        \"method_id\": 1,\n        \"rank\": 3\n    },\n    {\n        \"method_id\": 0,\n        \"rank\": 4\n    },\n    {\n        \"method_id\": 4,\n        \"rank\": 5\n    }\n]\n```"
}